Workbook

Sheet Trunk Rd C  
A1: LIMESTONE CR ROAD YEPPOON
A2: Trunk Road Section C - OP WORKS
B3: BILL OF QUANTITIES | D3: DATE | F3: 46204 | G3: REV A
C4: Item | D4: Qty. | E4: Unit | F4: Rate | G4: Total
A5: 3 | C5: STORMWATER DRAINAGE | F5: =SUM(G6:G23) -> 0
B6: 3.1 | C6: Supply, Excavate, Joint, Lay & Backfill incl compaction testing
B7: 3.1.1 | C7: 375mm dia. HDPE | D7: ='stormwater pipe calcs'!AJ46 -> 34.818 | E7: m | G7: =+F7*D7 -> 0
B8: 3.1.2 | C8: 675mm dia. RCP RRJ 'Class 3' | D8: ='stormwater pipe calcs'!AJ45 -> 58.268 | E8: m | G8: =+F8*D8 -> 0
B9: 3.1.3 | C9: 750mm dia. RCP RRJ 'Class 3' | D9: ='stormwater pipe calcs'!AJ44 -> 17.342 | E9: m | G9: =+F9*D9 -> 0
B10: 3.1.4 | C10: 3.6m x 0.9m RCBC | D10: 235.2 | E10: m | G10: =+F10*D10 -> 0
B11: 3.1.5 | C11: 3.6m x 1.2m RCBC | D11: 33.6 | E11: m | G11: =+F11*D11 -> 0
B12: 3.2 | C12: Supply & Install Concrete Pits with Lintel
B13: 3.2.1 | C13: 2.4m Lintel Type 'S' - STD CMDG Type A Gully Pit - SAG | D13: 2 | E13: each | G13: =+F13*D13 -> 0
B14: 3.2.2 | C14: 2.4m Lintel Type 'S' - STD CMDG Type A Gully Pit | D14: 1 | E14: each | G14: =+F14*D14 -> 0
B15: 3.2.3 | C15: 2.4m Lintel Type 'S' - Custom Pit (1200 x 900) | D15: 2 | E15: each | G15: =+F15*D15 -> 0
B16: 3.2.4 | C16: 2.4m Lintel Type 'S' - Custom Pit (1100x1100) | D16: 1 | E16: each | G16: =+F16*D16 -> 0
B17: 3.3 | C17: Supply, Excavate, Install & Backfill Headwall to suit:
B18: 3.3.1 | C18: 375mm DIA. HDPE (1/44) | D18: 1 | E18: each
B19: 3.3.2 | C19: 750mm DIA. RCP (40-1) | D19: 1 | E19: each
B20: 3.4 | C20: Base Slab for Culverts per structural Engineers Details | D20: 1072.3 | E20: m² | G20: =F20*D20 -> 0
B21: 3.5 | C21: 64 m Long Cast In-Situ Head Wall to Culverts (including Concrete Aprons) to Structural Engineers Details | D21: 2 | E21: Each | G21: =F21*D21 -> 0
B22: 3.6 | C22: Outlet Protection for Culvert System | D22: 1 | E22: each | G22: =F22*D22 -> 0
B23: 3.7 | C23: Outlet Protection for Headwalls | D23: 2 | E23: each | G23: =F23*D23 -> 0
A24: 4 | C24: SUBSOIL DRAINAGE | F24: =SUM(G25:G27) -> #REF!
B25: 4.1 | C25: Excavate, supply, bed, lay, joint and backfill pipe
B26: 4.1.1 | C26: 100mm Dia. Draincoil: As per Specification incl. filter "sock" | D26: =#REF! -> #REF! | E26: m | G26: =+F26*D26 -> #REF!
B27: 4.1.2 | C27: Subsoil drain flushing points (@ no greater than 50m Intervals) | D27: =D26/50 -> #REF! | E27: each | G27: =+F27*D27 -> #REF!

Sheet ST 1,2 RES BOQ 
A1: LIMESTONE CR ROAD YEPPOON
A2: STAGE 1 & 2 - OP WORKS
B3: BILL OF QUANTITIES | D3: DATE | F3: 46204 | G3: Rev A
C4: Item | D4: Qty. | E4: Unit | F4: Rate | G4: Total
A5: 3 | C5: STORMWATER DRAINAGE | F5: =SUM(G6:G30) -> 0
B6: 3.1 | C6: Supply, Excavate, Joint, Lay & Backfill incl compaction testing
B7: 3.1.1 | C7: 375mm dia. HDPE | D7: ='stormwater pipe calcs'!AJ10 -> 584.495 | E7: m | G7: =F7*D7 -> 0
B8: 3.1.2 | C8: 450mm dia. HDPE | D8: ='stormwater pipe calcs'!AJ9 -> 163.519 | E8: m | G8: =F8*D8 -> 0
B9: 3.1.3 | C9: 525mm dia. HDPE | D9: ='stormwater pipe calcs'!AJ8 -> 311.42 | E9: m | G9: =F9*D9 -> 0
B10: 3.1.4 | C10: 600mm dia. HDPE | D10: ='stormwater pipe calcs'!AJ7 -> 308.971 | E10: m | G10: =F10*D10 -> 0
B11: 3.1.5 | C11: 675mm dia. RCP RRJ 'Class 3' | D11: ='stormwater pipe calcs'!AJ6 -> 34.388 | E11: m | G11: =F11*D11 -> 0
B12: 3.1.6 | C12: 750mm dia. RCP RRJ 'Class 3' | D12: ='stormwater pipe calcs'!AJ5 -> 19.893 | E12: m | G12: =F12*D12 -> 0
B13: 3.1.7 | C13: 825mm dia. RCP RRJ 'Class 3' | D13: ='stormwater pipe calcs'!AJ4 -> 37.574 | E13: m | G13: =F13*D13 -> 0
B14: 3.1.8 | C14: 900mm dia. RCP RRJ 'Class 3' | D14: ='stormwater pipe calcs'!AJ3 -> 117.895 | E14: m | G14: =F14*D14 -> 0
B15: 3.2 | C15: Construct Concrete Pits
B16: 3.2.1 | C16: 2.4m Lintel Type 'S' - STD CMDG Type A Gully Pit - SAG | D16: 7 | E16: each | G16: =F16*D16 -> 0
B17: 3.2.2 | C17: 2.4m Lintel Type 'S' - STD CMDG Type A Gully Pit | D17: =67-7-7 -> 53 | E17: each | G17: =F17*D17 -> 0
B18: 3.3 | C18: Supply & Construct Custom Concrete Pits
B19: 3.3.1 | C19: Custom grated Junction Pit To plan Detail including Structural Design - Pit 5/1 (1100x900) | D19: 1 | E19: Item | G19: =F19*D19 -> 0
B20: 3.3.2 | C20: Custom grated Junction Pit To plan Detail including Structural Design - Pit 2/18 (2100x900) | D20: 1 | E20: Item | G20: =F20*D20 -> 0
B21: 3.3.3 | C21: Custom grated Junction Pit To plan Detail including Structural Design - Pit 3/18 (2100x1300) | D21: 1 | E21: Item | G21: =F21*D21 -> 0
B22: 3.3.4 | C22: Custom grated Junction Pit To plan Detail including Structural Design - Pit 4/18 (1300x1200) | D22: 1 | E22: Item | G22: =F22*D22 -> 0
B23: 3.3.5 | C23: Custom grated Junction Pit To plan Detail including Structural Design - Pit 2/20 (1200x900) | D23: 1 | E23: Item | G23: =F23*D23 -> 0
B24: 3.3.6 | C24: Custom grated Junction Pit To plan Detail including Structural Design - Pit 5/18 (1100x1200) | D24: 1 | E24: Item | G24: =F24*D24 -> 0
B25: 3.3.7 | C25: Custom grated Junction Pit To plan Detail including Structural Design - Pit 6/18 (1100x900) | D25: 1 | E25: Item | G25: =F25*D25 -> 0
B26: 3.4 | C26: Supply, Excavate, Install & Backfill Headwall to suit:
B27: 3.4.1 | C27: Twin 900mm DIA. RCP (1/18) | D27: 1 | E27: each | G27: =F27*D27 -> 0
B28: 3.4.2 | C28: Temporary headwall to suit 600mm DIA. HDPE (5/1) including tail out Swale | D28: 1 | E28: each | G28: =F28*D28 -> 0
B29: 3.4.3 | C29: Temporary headwall to suit 375mm DIA. HDPE (10/9) including tail out Swale | D29: 1 | E29: each | G29: =F29*D29 -> 0
B30: 3.5 | C30: Outlet Protection to headwall | D30: 1 | E30: each | G30: =F30*D30 -> 0
A31: 4 | C31: INTERLOT DRAINAGE | F31: =SUM(G32:G48) -> 0
B32: 4.1 | C32: Supply, excavate, bed, lay, joint and backfill pipe
B33: 4.1.1 | C33: 150mm Dia. uPVC. | D33: ='stormwater pipe calcs'!AJ16 -> 126.33 | E33: m | G33: =+F33*D33 -> 0
B34: 4.1.2 | C34: 200mm Dia. uPVC. | D34: ='stormwater pipe calcs'!AJ15 -> 122.869 | E34: m | G34: =+F34*D34 -> 0
B35: 4.1.3 | C35: 225mm Dia. uPVC. | D35: ='stormwater pipe calcs'!AJ14 -> 134.231 | E35: m | G35: =+F35*D35 -> 0
B36: 4.1.4 | C36: 300mm Dia. uPVC. | D36: ='stormwater pipe calcs'!AJ13 -> 250.37 | E36: m | G36: =+F36*D36 -> 0
B37: 4.2 | C37: Supply and Install Stormwater Junctions
B38: 4.2.1 | C38: Junctions to IAD pits | D38: 26 | E38: each | G38: =+F38*D38 -> 0
B39: 4.2.2 | C39: Supply and Install Kerb Adaptor in accordance with CMDG -R-061 | D39: 44 | E39: each | G39: =+F39*D39 -> 0
B40: 4.2.3 | C40: Supply and Install 100mm DIA uPVC junction to lot from Kerb Adaptor in Accordance with CMDG-R-061 | D40: 264 | E40: m | G40: =+F40*D40 -> 0
...

Sheet ST 3,4,5,6 RES BOQ  
A1: LIMESTONE CR ROAD YEPPOON
A2: Stage 3, 4, 5 & 6 - OP WORKS
B3: BILL OF QUANTITIES | D3: DATE | F3: 46204 | G3: REV A
C4: Item | D4: Qty. | E4: Unit | F4: Rate | G4: Total
A5: 3 | C5: STORMWATER DRAINAGE | F5: 0
B6: 3.1 | C6: Supply, Excavate, Joint, Lay & Backfill incl compaction testing
B7: 3.1.1 | C7: 375mm dia. HDPE | D7: 465.798 | E7: m | G7: 0
B8: 3.1.2 | C8: 450mm dia. HDPE | D8: 177.612 | E8: m | G8: 0
B9: 3.1.3 | C9: 525mm dia. HDPE | D9: 44.729 | E9: m | G9: 0
B10: 3.1.4 | C10: 600mm dia. HDPE | D10: 203.959 | E10: m | G10: 0
B11: 3.1.6 | C11: 750mm dia. RCP RRJ 'Class 3' | D11: 252.535 | E11: m | G11: 0
B12: 3.2 | C12: Construct Concrete Pits AUSPEC C223
B13: 3.2.1 | C13: 2.4m Lintel Type 'S' - STD CMDG Type A Gully Pit - SAG | D13: 6 | E13: each | G13: 0
B14: 3.2.2 | C14: 2.4m Lintel Type 'S' - STD CMDG Type A Gully Pit | D14: 30 | E14: each | G14: 0
B15: 3.3 | C15: Supply & Construct Custom Concrete Pits
B16: 3.3.1 | C16: Custom grated Junction Pit To plan Detail including Structural Design - Pit 4/1, Pit 2/1, Pit 3/1, Pit 6/9 (1100x900) | D16: 4 | E16: Item | G16: 0
B17: 3.3.2 | C17: Custom grated Junction Pit To plan Detail including Structural Design - Pit 2/80, Pit 1/82 (1100x900) | D17: 2 | E17: Item | G17: 0
B18: 3.3.3 | C18: Custom grated Junction Pit To plan Detail including Structural Design - Pit 2/9 (1100x1000) | D18: 1 | E18: Item | G18: 0
B19: 3.4 | C19: Supply, Excavate, Install & Backfill Headwall to suit:
B20: 3.4.1 | C20: 750mm DIA. RCP (1/1) | D20: 1 | E20: each | G20: 0
B21: 3.4.2 | C21: Twin 750mm DIA RCP (1/9) | D21: 1 | E21: each | G21: 0
B22: 3.4.3 | C22: 525mm DIA. HDPE (headwall into Western Basin) | D22: 1 | E22: each | G22: 0
B23: 3.5 | C23: Removal and Dispose of Temporary Headwalls Installed in Stage 1/2 | D23: 2 | E23: Each | G23: 0
B24: 3.5 | C24: Outlet Protection | D24: 3 | E24: each | G24: 0
A25: 4 | C25: INTERLOT DRAINAGE | F25: 0
B26: 4.1 | C26: Supply, excavate, bed, lay, joint and backfill pipe
B27: 4.1.1 | C27: 150mm Dia. uPVC. | D27: 45.326 | E27: m | G27: 0
B28: 4.1.2 | C28: 200mm Dia. uPVC. | D28: 40.484 | E28: m | G28: 0
B29: 4.1.3 | C29: 225mm Dia. uPVC. | D29: 325.365 | E29: m | G29: 0
B30: 4.1.4 | C30: 300mm Dia. uPVC. | D30: 55.159 | E30: m | G30: 0
C31: Supply and Install Stormwater Junctions
B32: 4.2.1 | C32: Junctions to IAD pits | D32: 25 | E32: each | G32: 0
B33: 4.2.2 | C33: Supply and Install Kerb Adaptor in accordance with CMDG -R-061 | D33: 39 | E33: each | G33: 0
B34: 4.2.3 | C34: Supply and Install 100mm DIA uPVC junction to lot from Kerb Adaptor in Accordance with CMDG-R-061 | D34: 234 | E34: m | G34: 0
B35: 4.3 | C35: Supply and Install Pre-Cast IAD Pits
B36: 4.3.1 | C36: Std. Inspection Pit 600 x 600 mm | D36: 7 | E36: each | G36: 0
B37: 4.3.2 | C37: Std. Inspection Pit 600 x 900 mm | D37: 12 | E37: each | G37: 0
B38: 4.3.3 | C38: Std. Inspection Pit 900 x 900 mm | D38: 6 | E38: each | G38: 0
B39: 4.4 | C39: Supply, Excavate, Install & Backfill Headwall to suit:
B40: 4.4.1 | C40: 225mm DIA. HDPE (1/15, 1/16) | D40: 2 | E40: Each | G40: 0
...

Sheet stormwater pipe calcs
A1: Stage 1 & 2 | AJ1: Total
A2: Road Drainage
A3: 900 | B3: 13.554 | C3: 13.554 | D3: 40.08 | E3: 40.08 | F3: 5.937 | G3: 4.69 | AJ3: =SUM(B3:AI3) -> 117.895
A4: =A3-75 -> 825 | B4: 37.574 | AJ4: =SUM(B4:AI4) -> 37.574
A5: =A4-75 -> 750 | B5: 9.183 | C5: 10.71 | AJ5: =SUM(B5:AI5) -> 19.893
A6: =A5-75 -> 675 | B6: 34.388 | AJ6: =SUM(B6:AI6) -> 34.388
A7: =A6-75 -> 600 | B7: 65.484 | C7: 16.377 | D7: 29.983 | E7: 27.612 | F7: 50.76 | G7: 24.759 | H7: 19.669 | I7: 20.383 | J7: 15.699 | K7: 13.27 | L7: 24.975 | AJ7: =SUM(B7:AI7) -> 308.971
A8: =A7-75 -> 525 | B8: 50.328 | C8: 47.873 | D8: 8.466 | E8: 4.806 | F8: 41.83 | G8: 9.975 | H8: 14.842 | I8: 45.832 | J8: 8.011 | K8: 38.949 | L8: 40.508 | AJ8: =SUM(B8:AI8) -> 311.42
A9: =A8-75 -> 450 | B9: 36.277 | C9: 13.487 | D9: 41.977 | E9: 43.163 | F9: 28.615 | AJ9: =SUM(B9:AI9) -> 163.519
A10: =A9-75 -> 375 | B10: 13.692 | C10: 11.139 | D10: 11.359 | E10: 10.007 | F10: 34.558 | G10: 9.333 | H10: 28.374 | I10: 14.341 | J10: 12.225 | K10: 9.687 | L10: 8.011 | M10: 28.182 | N10: 22.651 | O10: 22.517 | P10: 9.599 | Q10: 9.603 | R10: 31.124 | S10: 12.83 | T10: 10.631 | U10: 9.791 | V10: 9.039 | W10: 9.935 | X10: 20.635 | Y10: 28.166 | Z10: 18.985 | AA10: 12.133 | AB10: 40.672 | AC10: 40.82 | AD10: 11.606 | AE10: 38.363 | AF10: 8.031 | AG10: 13.714 | AH10: 12.742 | AJ10: =SUM(B10:AI10) -> 584.495
A12: IAD
A13: 300 | B13: 13.043 | C13: 34.028 | D13: 22.357 | E13: 56.007 | F13: 35.214 | G13: 25 | H13: 25.01 | I13: 11.938 | J13: 27.773 | AJ13: =SUM(B13:AI13) -> 250.37
A14: 225 | B14: 9.897 | C14: 8.824 | D14: 43.426 | E14: 4.072 | F14: 27 | G14: 6.659 | H14: 7.377 | I14: 26.976 | AJ14: =SUM(B14:AI14) -> 134.231
A15: 200 | B15: 27.146 | C15: 25.327 | D15: 35.351 | E15: 35.045 | AJ15: =SUM(B15:AI15) -> 122.869
A16: 150 | B16: 23.144 | C16: 46.863 | D16: 31.318 | E16: 25.005 | AJ16: =SUM(B16:AI16) -> 126.33
A17: 100 | B17: 31.156 | AJ17: =SUM(B17:AI17) -> 31.156
A23: Stage 3, 4, 5, 6
A24: Road Drainage
A25: 900
A26: =A25-75 -> 825
A27: =A26-75 -> 750 | B27: 88.332 | C27: 50.214 | D27: 13.211 | E27: 30.077 | F27: 14.417 | G27: 14.417 | H27: 41.867 | AJ27: =SUM(B27:AI27) -> 252.535
A28: =A27-75 -> 675
A29: =A28-75 -> 600 | B29: 9.768 | C29: 9.768 | D29: 10.35 | E29: 10.35 | F29: 8.759 | G29: 8.759 | H29: 16.516 | I29: 28.535 | J29: 28.118 | K29: 41.502 | L29: 7.757 | M29: 7.757 | N29: 8.01 | O29: 8.01 | AJ29: =SUM(B29:AI29) -> 203.959
A30: =A29-75 -> 525 | B30: 44.729 | AJ30: =SUM(B30:AI30) -> 44.729
A31: =A30-75 -> 450 | B31: 8.064 | C31: 37.596 | D31: 10.604 | E31: 8.142 | F31: 41.323 | G31: 12.203 | H31: 12.203 | I31: 12.203 | J31: 7.06 | K31: 7.06 | L31: 7.06 | M31: 4.698 | N31: 4.698 | O31: 4.698 | AJ31: =SUM(B31:AI31) -> 177.612
A32: =A31-75 -> 375 | B32: 62.41 | C32: 10.225 | D32: 7.962 | E32: 45.098 | F32: 19.937 | G32: 8.137 | H32: 12.88 | I32: 8.032 | J32: 21.536 | K32: 44.601 | L32: 28.324 | M32: 8.115 | N32: 9.603 | O32: 56.758 | P32: 50.26 | Q32: 7.658 | R32: 15.921 | S32: 39.47 | T32: 8.871 | AJ32: =SUM(B32:AI32) -> 465.798
A34: IAD
A35: 300 | B35: 16.448 | C35: 3.909 | D35: 16.604 | E35: 18.198 | AJ35: =SUM(B35:AI35) -> 55.159
A36: 225 | B36: 6.513 | C36: 39.913 | D36: 22.452 | E36: 18.342 | F36: 20.518 | G36: 26.607 | H36: 20.88 | I36: 17.294 | J36: 7.056 | K36: 34.636 | L36: 9.031 | M36: 3.226 | N36: 18.679 | O36: 21.242 | P36: 24.117 | Q36: 25.471 | R36: 9.388 | AJ36: =SUM(B36:AI36) -> 325.365
A37: 200 | B37: 20.307 | C37: 20.177 | AJ37: =SUM(B37:AI37) -> 40.484
A38: 150 | B38: 20.257 | C38: 25.069 | AJ38: =SUM(B38:AI38) -> 45.326
A43: Trunk Road
A44: 750 | B44: 17.342 | AJ44: =SUM(B44:AI44) -> 17.342
A45: 675 | B45: 41.931 | C45: 16.337 | AJ45: =SUM(B45:AI45) -> 58.268
A46: 375 | B46: 23.687 | C46: 11.131 | AJ46: =SUM(B46:AI46) -> 34.818
