Workbook

Sheet READ ME
B2: LIMESTONE CREEK ESTATE (5614) — YEPPOON | SEWER PRICING v3
B3: Rate basis: Tricore (TCS) internal cost sheet + supplier quotes + researched estimates
B7: BASIS — READ BEFORE USE
B8: 1. QUANTITIES from McIntosh Civil BOQ (Rev A). No independent take-off done; rates apply to their quantities.
B9: 2. LABOUR & PLANT now from your TCS cost sheet: in-ground crew $2,650.39/day (3-person, incl. operator); dry-hire plant day rates; +15% fuel & consumables on plant. Crews built on 'Rate Library'.
B10: 3. PRELIMS 10% (raised from your ~8% for this larger/longer project) + OVERHEAD 18% (your TCS rate) + wet weather 5%, applied as loadings on direct cost; MARGIN 15% on top.
B11: 4. PRODUCTION OUTPUTS reduced 15% across the board, per instruction (the m/day and ea/day figures shown are the already-reduced values).
B12: 5. MATERIALS: supplier-quoted rates retained (they were NOT overruled). Bedding sand now $39.75/m3 from your TCS sheet. Freight captured as 10% on material.
B13: 6. ESTIMATED RATES (orange on the Material Rate Register): RCBC 3.6m culverts, RCP >600, 525 HDPE, 200 uPVC, subsoil, bioretention media, and 250 water main are MY estimates - extrapolated conservatively (leaning high) from your quotes + industry research, because those items are quote-only with no public rate. VERIFY before use.
B14: 7. WATER MAIN priced on HDPE PN16 rates (your TCS sheet) per instruction, not PVC.
B15: 8. This file prices SEWER (Stages 1&2 and 3-6; sewer has no Trunk Road scope). Water & Stormwater run off the same engine and the same Rate Register, and get built into the 3-project split (Trunk Road / St 1-2 / St 3-6) next.
B16: 9. All ex-GST. Edit yellow cells; everything else recalculates.

Sheet Summary
B2: SEWER — PRICING SUMMARY (TCS basis)
B3: Limestone Creek Estate (5614) | Ex-GST | TCS labour/plant/OH, supplier materials, -15% production
B5: Package | C5: Amount (ex-GST)
B6: PROJECT 2 — Stages 1 & 2 (Sewer) | C6: ='ST 1,2 RES BOQ '!F5 -> 1511718.4
B7: PROJECT 3 — Stages 3-6 (Sewer) | C7: ='ST 3,4,5,6 RES BOQ '!F5 -> 893178.51
B8: TOTAL SEWER (ex-GST) | C8: =C6+C7 -> 2404896.9
B9: GST (10%) | C9: =C8*0.1 -> 240489.69
B10: TOTAL incl. GST | C10: =C8+C9 -> 2645386.6
B12: PROJECT 1 (Trunk Road): no sewer scope. Water & Stormwater will populate all three projects.
B13: Provisional water-charged ground carries a rate but no quantity (excluded until a qty is set).

Sheet Rate Library
A1: RATE LIBRARY (TCS basis)
A2: Yellow = edit. Black = calculated. Ex-GST.
A4: A. LABOUR ($/day, TCS - 10hr day, FIFO all-in)
A5: Tradesman / Leading Hand | B5: 1231.14 | C5: $/day
A6: Plumber / Operator | B6: 941.16 | C6: $/day
A7: T/A & Apprentice | B7: 768.07 | C7: $/day
A8: In-ground crew (3-person) | B8: 2650.39 | C8: $/day
A10: B. PLANT (dry-hire $/day, TCS)
A11: Excavator 20-24t | B11: 314.29 | C11: $/day
A12: Excavator 8t | B12: 261.17 | C12: $/day
A13: Tipper truck <6t | B13: 171.43 | C13: $/day
A14: Trench roller (dbl drum) | B14: 165 | C14: $/day
A15: Upright rammer / wacker | B15: 34.29 | C15: $/day
A16: Trench shield / shoring | B16: 350 | C16: $/day
A17: Dewatering pump + wellpoints | B17: 850 | C17: $/day
A18: Fuel & consumables (on plant) | B18: 0.15 | C18: %
A20: C. CREWS ($/day, derived)
A21: Mains crew (in-ground + exc/truck/roller/wacker) | B21: =B8+(B11+B13+B14+B15)*(1+B18) -> 3438.1515 | C21: $/day
A22: Structures crew (in-ground + 8t exc/truck) | B22: =B8+(B12+B13)*(1+B18) -> 3147.88 | C22: $/day
A24: D. MATERIALS ($/unit ex-GST, ex-freight)
A25: DN150 sewer pipe (uPVC SN8 RRJ) | B25: 25.5 | C25: $/m
A26: DN300 sewer pipe (uPVC SN8 RRJ) | B26: 95.1 | C26: $/m
A27: Bedding sand, delivered | B27: 39.75 | C27: $/m3
A28: Manhole assembly <1.5m | B28: =B44 -> 4135.16 | C28: $/ea
A29: Manhole assembly 1.5-3m | B29: =B45 -> 5603.49 | C29: $/ea
A30: Manhole assembly >3m | B30: =B46 -> 7071.82 | C30: $/ea
A31: Lamphole assembly | B31: 950 | C31: $/ea
A32: Property junction fitting | B32: 80.72 | C32: $/ea
A33: 150mm bend fitting | B33: 71.45 | C33: $/ea
A34: Marker tape / sundries | B34: 3 | C34: $/m
A36: D2. MANHOLE COMPONENTS (higher of suppliers)
A37: 1050 fibreglass base | B37: 722.4 | C37: $/ea
A38: Concrete shaft 1050x1200 | B38: 1468.33 | C38: $/ea
A39: Concrete shaft 1050x300 | B39: 449.9 | C39: $/ea
A40: Reducer slab CL D | B40: 765.02 | C40: $/ea
A41: Cover & surround CL D | B41: 799 | C41: $/ea
A42: Waterstop per MH | B42: 380.41 | C42: $/ea
A44: MH <1.5m | B44: =B37+B38+B40+B41+B42 -> 4135.16 | C44: $/ea
A45: MH 1.5-3m | B45: =B37+2*B38+B40+B41+B42 -> 5603.49 | C45: $/ea
A46: MH >3m | B46: =B37+3*B38+B40+B41+B42 -> 7071.82 | C46: $/ea
...

Sheet Rate Buildups
A1: RATE BUILDUPS (first principles, $/day basis)
A2: Yellow = production output (already -15%). Crew $/day and loadings from Rate Library. Rate (col M) links to BOQ.
A4: Ref | B4: Description | C4: Unit | D4: Prod /day | E4: Crew $/day | F4: Labour+ Plant $/u | G4: Material+ Frt $/u | H4: Bed+Sun +Shore $/u | I4: Direct $/u | J4: Indirect $/u | K4: Subtotal $/u | L4: Margin $/u | M4: RATE $/unit
A5: SW-01 | B5: 150mm sewer, up to 1.5m | C5: m | D5: 59.5 | E5: ='Rate Library'!$B$21 -> 3438.1515 | F5: =E5/D5 -> 57.784059 | G5: ='Rate Library'!$B$25*(1+'Rate Library'!$B$54) -> 28.05 | H5: ='Rate Library'!$B$53*'Rate Library'!$B$27+'Rate Library'!$B$34 -> 16.9125 | I5: =F5+G5+H5 -> 102.74656 | J5: =I5*('Rate Library'!$B$49+'Rate Library'!$B$50+'Rate Library'!$B$51) -> 33.906364 | K5: =I5+J5 -> 136.65292 | L5: =K5*'Rate Library'!$B$52 -> 20.497938 | M5: =K5+L5 -> 157.15086
A6: SW-02 | B6: 150mm sewer, 1.5-3.0m | C6: m | D6: 40.8 | E6: ='Rate Library'!$B$21 -> 3438.1515 | F6: =E6/D6 -> 84.268419 | G6: ='Rate Library'!$B$25*(1+'Rate Library'!$B$54) -> 28.05 | H6: ='Rate Library'!$B$53*'Rate Library'!$B$27+'Rate Library'!$B$34+'Rate Library'!$B$16/D6 -> 25.490931 | I6: =F6+G6+H6 -> 137.80935 | J6: =I6*('Rate Library'!$B$49+'Rate Library'!$B$50+'Rate Library'!$B$51) -> 45.477086 | K6: =I6+J6 -> 183.28644 | L6: =K6*'Rate Library'!$B$52 -> 27.492965 | M6: =K6+L6 -> 210.7794
A7: SW-03 | B7: 150mm sewer, over 3.0m | C7: m | D7: 22.1 | E7: ='Rate Library'!$B$21 -> 3438.1515 | F7: =E7/D7 -> 155.57247 | G7: ='Rate Library'!$B$25*(1+'Rate Library'!$B$54) -> 28.05 | H7: ='Rate Library'!$B$53*'Rate Library'!$B$27+'Rate Library'!$B$34+'Rate Library'!$B$16/D7 -> 32.749604 | I7: =F7+G7+H7 -> 216.37207 | J7: =I7*('Rate Library'!$B$49+'Rate Library'!$B$50+'Rate Library'!$B$51) -> 71.402783 | K7: =I7+J7 -> 287.77485 | L7: =K7*'Rate Library'!$B$52 -> 43.166228 | M7: =K7+L7 -> 330.94108
A8: SW-04 | B8: 300mm sewer, 1.5-3.0m | C8: m | D8: 34 | E8: ='Rate Library'!$B$21 -> 3438.1515 | F8: =E8/D8 -> 101.1221 | G8: ='Rate Library'!$B$26*(1+'Rate Library'!$B$54) -> 104.61 | H8: ='Rate Library'!$B$53*'Rate Library'!$B$27+'Rate Library'!$B$34+'Rate Library'!$B$16/D8 -> 27.206618 | I8: =F8+G8+H8 -> 232.93872 | J8: =I8*('Rate Library'!$B$49+'Rate Library'!$B$50+'Rate Library'!$B$51) -> 76.869778 | K8: =I8+J8 -> 309.8085 | L8: =K8*'Rate Library'!$B$52 -> 46.471275 | M8: =K8+L8 -> 356.27977
A9: SW-05 | B9: 300mm sewer, over 3.0m | C9: m | D9: 18.7 | E9: ='Rate Library'!$B$21 -> 3438.1515 | F9: =E9/D9 -> 183.85837 | G9: ='Rate Library'!$B$26*(1+'Rate Library'!$B$54) -> 104.61 | H9: ='Rate Library'!$B$53*'Rate Library'!$B$27+'Rate Library'!$B$34+'Rate Library'!$B$16/D9 -> 35.629078 | I9: =F9+G9+H9 -> 324.09745 | J9: =I9*('Rate Library'!$B$49+'Rate Library'!$B$50+'Rate Library'!$B$51) -> 106.95216 | K9: =I9+J9 -> 431.0496 | L9: =K9*'Rate Library'!$B$52 -> 64.657441 | M9: =K9+L9 -> 495.70704
A10: SW-06 | B10: Water-charged ground (prov., EXTRA-OVER) | C10: m | D10: 25.5 | E10: ='Rate Library'!$B$17 -> 850 | F10: =E10/D10 -> 33.333333 | G10: 0 | H10: 0 | I10: =F10+G10+H10 -> 33.333333 | J10: =I10*('Rate Library'!$B$49+'Rate Library'!$B$50+'Rate Library'!$B$51) -> 11 | K10: =I10+J10 -> 44.333333 | L10: =K10*'Rate Library'!$B$52 -> 6.65 | M10: =K10+L10 -> 50.983333
A11: SW-07 | B11: Manhole, up to 1.5m | C11: ea | D11: 2.13 | E11: ='Rate Library'!$B$22 -> 3147.88 | F11: =E11/D11 -> 1477.8779 | G11: ='Rate Library'!$B$28*(1+'Rate Library'!$B$54) -> 4548.676 | H11: =150 -> 150 | I11: =F11+G11+H11 -> 6176.5539 | J11: =I11*('Rate Library'!$B$49+'Rate Library'!$B$50+'Rate Library'!$B$51) -> 2038.2628 | K11: =I11+J11 -> 8214.8167 | L11: =K11*'Rate Library'!$B$52 -> 1232.2225 | M11: =K11+L11 -> 9447.0392
A12: SW-08 | B12: Manhole, 1.5-3.0m | C12: ea | D12: 1.28 | E12: ='Rate Library'!$B$22 -> 3147.88 | F12: =E12/D12 -> 2459.2812 | G12: ='Rate Library'!$B$29*(1+'Rate Library'!$B$54) -> 6163.839 | H12: =150+'Rate Library'!$B$16/D12 -> 423.4375 | I12: =F12+G12+H12 -> 9046.5577 | J12: =I12*('Rate Library'!$B$49+'Rate Library'!$B$50+'Rate Library'!$B$51) -> 2985.3641 | K12: =I12+J12 -> 12031.922 | L12: =K12*'Rate Library'!$B$52 -> 1804.7883 | M12: =K12+L12 -> 13836.71
A13: SW-09 | B13: Manhole, over 3.0m | C13: ea | D13: 0.68 | E13: ='Rate Library'!$B$22 -> 3147.88 | F13: =E13/D13 -> 4629.2353 | G13: ='Rate Library'!$B$30*(1+'Rate Library'!$B$54) -> 7779.002 | H13: =150+'Rate Library'!$B$16/D13 -> 664.70588 | I13: =F13+G13+H13 -> 13072.943 | J13: =I13*('Rate Library'!$B$49+'Rate Library'!$B$50+'Rate Library'!$B$51) -> 4314.0712 | K13: =I13+J13 -> 17387.014 | L13: =K13*'Rate Library'!$B$52 -> 2608.0522 | M13: =K13+L13 -> 19995.067
A14: SW-10 | B14: Lamphole, up to 1.5m | C14: ea | D14: 2.55 | E14: ='Rate Library'!$B$22 -> 3147.88 | F14: =E14/D14 -> 1234.4627 | G14: ='Rate Library'!$B$31*(1+'Rate Library'!$B$54) -> 1045 | H14: =80 -> 80 | I14: =F14+G14+H14 -> 2359.4627 | J14: =I14*('Rate Library'!$B$49+'Rate Library'!$B$50+'Rate Library'!$B$51) -> 778.62271 | K14: =I14+J14 -> 3138.0855 | L14: =K14*'Rate Library'!$B$52 -> 470.71282 | M14: =K14+L14 -> 3608.7983
A15: SW-11 | B15: Lamphole, 1.5-3.0m | C15: ea | D15: 1.7 | E15: ='Rate Library'!$B$22 -> 3147.88 | F15: =E15/D15 -> 1851.6941 | G15: ='Rate Library'!$B$31*(1+'Rate Library'!$B$54) -> 1045 | H15: =80+'Rate Library'!$B$16/D15 -> 285.88235 | I15: =F15+G15+H15 -> 3182.5765 | J15: =I15*('Rate Library'!$B$49+'Rate Library'!$B$50+'Rate Library'!$B$51) -> 1050.2502 | K15: =I15+J15 -> 4232.8267 | L15: =K15*'Rate Library'!$B$52 -> 634.92401 | M15: =K15+L15 -> 4867.7507
A16: SW-12 | B16: Property junction - Type B | C16: ea | D16: 6.8 | E16: ='Rate Library'!$B$22 -> 3147.88 | F16: =E16/D16 -> 462.92353 | G16: ='Rate Library'!$B$32*(1+'Rate Library'!$B$54) -> 88.792 | H16: =50 -> 50 | I16: =F16+G16+H16 -> 601.71553 | J16: =I16*('Rate Library'!$B$49+'Rate Library'!$B$50+'Rate Library'!$B$51) -> 198.56612 | K16: =I16+J16 -> 800.28165 | L16: =K16*'Rate Library'!$B$52 -> 120.04225 | M16: =K16+L16 -> 920.3239
A17: SW-13 | B17: Property junction - Type C1 | C17: ea | D17: 5.1 | E17: ='Rate Library'!$B$22 -> 3147.88 | F17: =E17/D17 -> 617.23137 | G17: ='Rate Library'!$B$32*(1+'Rate Library'!$B$54) -> 88.792 | H17: =50 -> 50 | I17: =F17+G17+H17 -> 756.02337 | J17: =I17*('Rate Library'!$B$49+'Rate Library'!$B$50+'Rate Library'!$B$51) -> 249.48771 | K17: =I17+J17 -> 1005.5111 | L17: =K17*'Rate Library'!$B$52 -> 150.82666 | M17: =K17+L17 -> 1156.3377
A18: SW-14 | B18: Property junction - Type C2 | C18: ea | D18: 4.25 | E18: ='Rate Library'!$B$22 -> 3147.88 | F18: =E18/D18 -> 740.67765 | G18: ='Rate Library'!$B$32*(1+'Rate Library'!$B$54) -> 88.792 | H18: =50 -> 50 | I18: =F18+G18+H18 -> 879.46965 | J18: =I18*('Rate Library'!$B$49+'Rate Library'!$B$50+'Rate Library'!$B$51) -> 290.22498 | K18: =I18+J18 -> 1169.6946 | L18: =K18*'Rate Library'!$B$52 -> 175.45419 | M18: =K18+L18 -> 1345.1488
A19: SW-15 | B19: Property junction - Type D | C19: ea | D19: 3.4 | E19: ='Rate Library'!$B$22 -> 3147.88 | F19: =E19/D19 -> 925.84706 | G19: ='Rate Library'!$B$32*(1+'Rate Library'!$B$54) -> 88.792 | H19: =50 -> 50 | I19: =F19+G19+H19 -> 1064.6391 | J19: =I19*('Rate Library'!$B$49+'Rate Library'!$B$50+'Rate Library'!$B$51) -> 351.33089 | K19: =I19+J19 -> 1415.9699 | L19: =K19*'Rate Library'!$B$52 -> 212.39549 | M19: =K19+L19 -> 1628.3654
A20: SW-16 | B20: 150mm sewer bend | C20: ea | D20: 8.5 | E20: ='Rate Library'!$B$22 -> 3147.88 | F20: =E20/D20 -> 370.33882 | G20: ='Rate Library'!$B$33*(1+'Rate Library'!$B$54) -> 78.595 | H20: =20 -> 20 | I20: =F20+G20+H20 -> 468.93382 | J20: =I20*('Rate Library'!$B$49+'Rate Library'!$B$50+'Rate Library'!$B$51) -> 154.74816 | K20: =I20+J20 -> 623.68199 | L20: =K20*'Rate Library'!$B$52 -> 93.552298 | M20: =K20+L20 -> 717.23428
A21: SW-17 | B21: Connect to existing MH (allowance) | C21: ea | D21: 0.85 | E21: ='Rate Library'!$B$22 -> 3147.88 | F21: =E21/D21 -> 3703.3882 | G21: =400 -> 400 | H21: =300 -> 300 | I21: =F21+G21+H21 -> 4403.3882 | J21: =I21*('Rate Library'!$B$49+'Rate Library'!$B$50+'Rate Library'!$B$51) -> 1453.1181 | K21: =I21+J21 -> 5856.5064 | L21: =K21*'Rate Library'!$B$52 -> 878.47595 | M21: =K21+L21 -> 6734.9823
A24: TESTING & COMMISSIONING — unit rate inputs
A25: CCTV inspection & reporting | B25: 4.5 | C25: $/m
A26: Vacuum testing of manholes | B26: 180 | C26: $/MH
A27: Pressure testing of main | B27: 2.5 | C27: $/m
A29: STAGE LUMP SUMS (item — incl. margin)
A30: Vacuum testing - Stage 1 & 2 | M30: =$B$26*SUM('ST 1,2 RES BOQ '!D14:D16)*(1+'Rate Library'!$B$52) -> 10557
A31: Pressure testing - Stage 1 & 2 | M31: =$B$27*SUM('ST 1,2 RES BOQ '!D7:D11)*(1+'Rate Library'!$B$52) -> 7834.375
A32: CCTV - Stage 1 & 2 | M32: =$B$25*SUM('ST 1,2 RES BOQ '!D7:D11)*(1+'Rate Library'!$B$52) -> 14101.875
A33: Vacuum testing - Stage 3-6 | M33: =$B$26*SUM('ST 3,4,5,6 RES BOQ '!D12:D14)*(1+'Rate Library'!$B$52) -> 6831
A34: Pressure testing - Stage 3-6 | M34: =$B$27*SUM('ST 3,4,5,6 RES BOQ '!D7:D9)*(1+'Rate Library'!$B$52) -> 4973.75
A35: CCTV - Stage 3-6 | M35: =$B$25*SUM('ST 3,4,5,6 RES BOQ '!D7:D9)*(1+'Rate Library'!$B$52) -> 8952.75

Sheet Material Rate Register
A1: MATERIAL RATE REGISTER — all packages (ex-GST, supply, ex-freight)
A2: Source key: QUOTED = supplier quotation (higher of two used). TCS = your cost sheet. ESTIMATE (orange) = my extrapolated/researched rate, leaning conservative — VERIFY.
A4: Category | B4: Item | C4: Unit | D4: Rate | E4: Source / basis
A5: SEWER | B5: DN150 sewer pipe uPVC SN8 RRJ | C5: m | D5: 25.5 | E5: Tradelink Q1065005 (higher of Tradelink/Reece)
A6: SEWER | B6: DN300 sewer pipe uPVC SN8 RRJ | C6: m | D6: 95.1 | E6: Tradelink Q1065005
A7: SEWER | B7: Bedding sand delivered | C7: m3 | D7: 39.75 | E7: TCS Material Rates_Master
A8: SEWER | B8: Manhole 1.5-3m (assembly) | C8: ea | D8: 5603.49 | E8: Reece/Jaybro/Tradelink components, higher of each
A9: SEWER | B9: Property junction fitting | C9: ea | D9: 80.72 | E9: Reece Q459011816
A10: SEWER | B10: 150mm bend | C10: ea | D10: 71.45 | E10: Reece Q459011816
A11: SEWER | B11: Lamphole assembly | C11: ea | D11: 1500 | E11: ESTIMATE - not quoted
A12: STORMWATER pipe | B12: 375 HDPE SN8 | C12: m | D12: 92.01 | E12: Reece Q459014445 (higher of Reece/Iplex)
A13: STORMWATER pipe | B13: 450 HDPE SN8 | C13: m | D13: 81.26 | E13: Iplex Q646120
A14: STORMWATER pipe | B14: 525 HDPE SN8 | C14: m | D14: 150 | E14: ESTIMATE - interpolated 450/600, lean high
A15: STORMWATER pipe | B15: 600 HDPE SN8 | C15: m | D15: 226.03 | E15: Reece Q459014445
A16: STORMWATER pipe | B16: 375 RCP Cl4 (+ring) | C16: m | D16: 138.9 | E16: Reece Q459014445 (higher of Reece/Humes)
... A42: WATER main (HDPE) | B42: DN250 (HDPE PN16 rate) | C42: m | D42: 58 | E42: ESTIMATE - extrapolated from TCS 200 HDPE, lean high

Sheet ST 1,2 RES BOQ 
A1: LIMESTONE CR ROAD YEPPOON
A2: STAGE 1 & 2 - OP WORKS
B3: BILL OF QUANTITIES | D3: DATE | F3: 46204 | G3: Rev A
C4: Item | D4: Qty. | E4: Unit | F4: Rate | G4: Total
A5: 6 | C5: SEWER RETICULATION | F5: =SUM(G6:G34) -> 1511718.4
B6: 6.1 | C6: Supply, Excavate, bed, lay, joint & backfill incl compaction testing & tape
B7: 6.1.1 | C7: 150mm sewer up to 1.50m deep | D7: 667 | E7: m | F7: ='Rate Buildups'!$M$5 -> 157.15086 | G7: =+F7*D7 -> 104819.62
B8: 6.1.2 | C8: 150mm sewer 1.50m to 3.0m deep | D8: 1410 | E8: m | F8: ='Rate Buildups'!$M$6 -> 210.7794 | G8: =+F8*D8 -> 297198.96
B9: 6.1.3 | C9: 150mm sewer over 3.0m deep | D9: 27 | E9: m | F9: ='Rate Buildups'!$M$7 -> 330.94108 | G9: =+F9*D9 -> 8935.4092
B10: 6.1.4 | C10: 300mm sewer 1.50m to 3.0m deep | D10: 591 | E10: m | F10: ='Rate Buildups'!$M$8 -> 356.27977 | G10: =+F10*D10 -> 210561.35
B11: 6.1.5 | C11: 300mm sewer over 3.0m deep | D11: 30 | E11: m | F11: ='Rate Buildups'!$M$9 -> 495.70704 | G11: =+F11*D11 -> 14871.211
B12: 6.1.6 | C12: Provisional Item - Allowance for Excavation and Installation in Water Charged Ground | E12: m | F12: ='Rate Buildups'!$M$10 -> 50.983333 | G12: =+F12*D12 -> 0
B13: 6.2 | C13: Construct Manholes
B14: 6.2.1 | C14: Up to 1.5m Deep | D14: 13 | E14: each | F14: ='Rate Buildups'!$M$11 -> 9447.0392 | G14: =+F14*D14 -> 122811.51
B15: 6.2.2 | C15: 1.5m to 3m Deep | D15: 34 | E15: each | F15: ='Rate Buildups'!$M$12 -> 13836.71 | G15: =+F15*D15 -> 470448.14
B16: 6.2.3 | C16: Over 3m Deep | D16: 4 | E16: each | F16: ='Rate Buildups'!$M$13 -> 19995.067 | G16: =+F16*D16 -> 79980.266
B17: 6.3 | C17: Construct Lampholes
B18: 6.3.1 | C18: Construct Lampholes to 1.5m | D18: 7 | E18: each | F18: ='Rate Buildups'!$M$14 -> 3608.7983 | G18: =+F18*D18 -> 25261.588
B19: 6.3.2 | C19: Construct Lampholes 1.5 to 3m | D19: 3 | E19: each | F19: ='Rate Buildups'!$M$15 -> 4867.7507 | G19: =+F19*D19 -> 14603.252
B20: 6.4 | C20: House Junctions - into line | E20: each | G20: =+F20*D20 -> 0
B21: 6.4.1 | C21: 100mm dia property sewer junction - Type B | D21: 26 | E21: each | F21: ='Rate Buildups'!$M$16 -> 920.3239 | G21: =+F21*D21 -> 23928.421
B22: 6.4.2 | C22: 100mm dia property sewer junction - Type C1 | D22: 21 | E22: each | F22: ='Rate Buildups'!$M$17 -> 1156.3377 | G22: =+F22*D22 -> 24283.093
B23: 6.4.3 | C23: 100mm dia property sewer junction - Type C2 | D23: 27 | E23: each | F23: ='Rate Buildups'!$M$18 -> 1345.1488 | G23: =+F23*D23 -> 36319.018
B24: 6.4.4 | C24: 100mm dia property sewer junction - Type D | D24: 12 | E24: each | F24: ='Rate Buildups'!$M$19 -> 1628.3654 | G24: =+F24*D24 -> 19540.385
B25: 6.5 | C25: Bends
B26: 6.5.1 | C26: 150mm 6° Bends | D26: 12 | E26: each | F26: ='Rate Buildups'!$M$20 -> 717.23428 | G26: =F26*D26 -> 8606.8114
B27: 6.5.2 | C27: 150mm 11¼ ° Bends | D27: 2 | E27: each | F27: ='Rate Buildups'!$M$20 -> 717.23428 | G27: =F27*D27 -> 1434.4686
B28: 6.5.3 | C28: 150mm 22½ ° Bends | D28: 1 | E28: each | F28: ='Rate Buildups'!$M$20 -> 717.23428 | G28: =F28*D28 -> 717.23428
B29: 6.5.4 | C29: 150mm 45 ° Bends | D29: 2 | E29: each | F29: ='Rate Buildups'!$M$20 -> 717.23428 | G29: =F29*D29 -> 1434.4686
B30: 6.5.5 | C30: Connect to existing Manhole by Livingstone Shire | D30: 2 | E30: each | F30: ='Rate Buildups'!$M$21 -> 6734.9823 | G30: =F30*D30 -> 13469.965
B31: 6.6 | C31: Commissioning sewer main
B32: 6.6.1 | C32: Vaccum testing manholes | D32: 1 | E32: item | F32: ='Rate Buildups'!$M$30 -> 10557 | G32: =+F32*D32 -> 10557
B33: 6.6.2 | C33: Pressure testing of sewer | D33: 1 | E33: item | F33: ='Rate Buildups'!$M$31 -> 7834.375 | G33: =+F33*D33 -> 7834.375
B34: 6.6.3 | C34: CCTV inspection & reporting | D34: 1 | E34: item | F34: ='Rate Buildups'!$M$32 -> 14101.875 | G34: =+F34*D34 -> 14101.875

Sheet ST 3,4,5,6 RES BOQ  
A1: LIMESTONE CR ROAD YEPPOON
A2: Stage 3, 4, 5 & 6 - OP WORKS
B3: BILL OF QUANTITIES | D3: DATE | F3: 46204 | G3: REV A
C4: Item | D4: Qty. | E4: Unit | F4: Rate | G4: Total
A5: 6 | C5: SEWER RETICULATION | F5: =SUM(G6:G32) -> 893178.51
B6: 6.1 | C6: Supply, Excavate, bed, lay, joint & backfill incl compaction testing & tape
B7: 6.1.1 | C7: 150mm sewer up to 1.50m deep | D7: 1011 | E7: m | F7: ='Rate Buildups'!$M$5 -> 157.15086 | G7: =+F7*D7 -> 158879.52
B8: 6.1.2 | C8: 150mm sewer 1.50m to 3.0m deep | D8: 554 | E8: m | F8: ='Rate Buildups'!$M$6 -> 210.7794 | G8: =+F8*D8 -> 116771.79
B9: 6.1.3 | C9: 150mm sewer over 3.0m deep | D9: 165 | E9: m | F9: ='Rate Buildups'!$M$7 -> 330.94108 | G9: =+F9*D9 -> 54605.278
B10: 6.1.4 | C10: Provisional Item - Allowance for Excavation and Installation in Water Charged Ground | E10: m | F10: ='Rate Buildups'!$M$10 -> 50.983333 | G10: =+F10*D10 -> 0
B11: 6.2 | C11: Construct Manholes
B12: 6.2.1 | C12: Up to 1.5m Deep | D12: 18 | E12: each | F12: ='Rate Buildups'!$M$11 -> 9447.0392 | G12: =+F12*D12 -> 170046.71
B13: 6.2.2 | C13: 1.5m to 3m Deep | D13: 12 | E13: each | F13: ='Rate Buildups'!$M$12 -> 13836.71 | G13: =+F13*D13 -> 166040.52
B14: 6.2.3 | C14: Over 3m Deep | D14: 3 | E14: each | F14: ='Rate Buildups'!$M$13 -> 19995.067 | G14: =+F14*D14 -> 59985.2
B15: 6.3 | C15: Construct Lampholes
B16: 6.3.1 | C16: Construct Lampholes to 1.5m | D16: 10 | E16: each | F16: ='Rate Buildups'!$M$14 -> 3608.7983 | G16: =+F16*D16 -> 36087.983
B17: 6.3.2 | C17: Construct Lampholes 1.5 to 3m | D17: 1 | E17: each | F17: ='Rate Buildups'!$M$15 -> 4867.7507 | G17: =+F17*D17 -> 4867.7507
B18: 6.4 | C18: House Junctions (including manhole inlets) | E18: each | G18: =+F18*D18 -> 0
B19: 6.4.1 | C19: 100mm dia property sewer junction - Type B | D19: 27 | E19: each | F19: ='Rate Buildups'!$M$16 -> 920.3239 | G19: =+F19*D19 -> 24848.745
B20: 6.4.2 | C20: 100mm dia property sewer junction - Type C1 | D20: 27 | E20: each | F20: ='Rate Buildups'!$M$17 -> 1156.3377 | G20: =+F20*D20 -> 31221.119
B21: 6.4.3 | C21: 100mm dia property sewer junction - Type C2 | D21: 11 | E21: each | F21: ='Rate Buildups'!$M$18 -> 1345.1488 | G21: =+F21*D21 -> 14796.637
B22: 6.5 | C22: Bends
B23: 6.5.1 | C23: 150mm 6° Bends | D23: 18 | E23: each | F23: ='Rate Buildups'!$M$20 -> 717.23428 | G23: =F23*D23 -> 12910.217
B24: 6.5.2 | C24: 150mm 11¼ ° Bends | D24: 5 | E24: each | F24: ='Rate Buildups'!$M$20 -> 717.23428 | G24: =F24*D24 -> 3586.1714
B25: 6.5.3 | C25: 150mm 22½ ° Bends | D25: 3 | E25: each | F25: ='Rate Buildups'!$M$20 -> 717.23428 | G25: =F25*D25 -> 2151.7028
B26: 6.5.4 | C26: 150mm 33¾° Bends | D26: 2 | E26: each | F26: ='Rate Buildups'!$M$20 -> 717.23428 | G26: =F26*D26 -> 1434.4686
B27: 6.5.5 | C27: 150mm 45 ° Bends | D27: 1 | E27: each | F27: ='Rate Buildups'!$M$20 -> 717.23428 | G27: =F27*D27 -> 717.23428
B28: 6.5.4 | C28: Connect to existing Manhole by Livingstone Shire | D28: 2 | E28: each | F28: ='Rate Buildups'!$M$21 -> 6734.9823 | G28: =F28*D28 -> 13469.965
B29: 6.6 | C29: Commissioning sewer main
B30: 6.6.1 | C30: Vaccum testing manholes | D30: 1 | E30: each | F30: ='Rate Buildups'!$M$33 -> 6831 | G30: =+F30*D30 -> 6831
B31: 6.6.2 | C31: Pressure testing of sewer | D31: 1 | E31: item | F31: ='Rate Buildups'!$M$34 -> 4973.75 | G31: =+F31*D31 -> 4973.75
B32: 6.6.3 | C32: CCTV inspection & reporting | D32: 1 | E32: item | F32: ='Rate Buildups'!$M$35 -> 8952.75 | G32: =+F32*D32 -> 8952.75

Sheet stormwater pipe calcs
A1: Stage 1 & 2 | AJ1: Total
A2: Road Drainage
A3: 900 | B3: 13.554 | C3: 13.554 | D3: 40.08 | E3: 40.08 | F3: 5.937 | G3: 4.69 | AJ3: =SUM(B3:AI3) -> 117.895
A4: =A3-75 -> 825 | B4: 37.574 | AJ4: =SUM(B4:AI4) -> 37.574
A5: =A4-75 -> 750 | B5: 9.183 | C5: 10.71 | AJ5: =SUM(B5:AI5) -> 19.893
A6: =A5-75 -> 675 | B6: 34.388 | AJ6: =SUM(B6:AI6) -> 34.388
A7: =A6-75 -> 600 | B7: 65.484 | C7: 16.377 | D7: 29.983 | E7: 27.612 | F7: 50.76 | G7: 24.759 | H7: 19.669 | I7: 20.383 | J7: 15.699 | K7: 13.27 | L7: 24.975 | AJ7: =SUM(B7:AI7) -> 308.971
A8: =A7-75 -> 525 | B8: 50.328 | C8: 47.873 | D8: 8.466 | E8: 4.806 | F8: 41.83 | G8: 9.975 | H8: 14.842 | I8: 45.832 | J8: 8.011 | K8: 38.949 | L8: 40.508 | AJ8: =SUM(B8:AI8) -> 311.42
A9: =A8-75 -> 450 | B9: 36.277 | C9: 13.487 | D9: 41.977 | E9: 43.163 | F9: 28.615 | AJ9: =SUM(B9:AI9) -> 163.519
A10: =A9-75 -> 375 | B10: 13.692 | C10: 11.139 | D10: 11.359 | E10: 10.007 | F10: 34.558 | G10: 9.333 | H10: 28.374 | I10: 14.341 | J10: 12.225 | K10: 9.687 | L10: 8.011 | M10: 28.182 | N10: 22.651 | O10: 22.517 | P10: 9.599 | Q10: 9.603 | R10: 31.124 | S10: 12.83 | T10: 10.631 | U10: 9.791 | V10: 9.039 | W10: 9.935 | X10: 20.635 | Y10: 28.166 | Z10: 18.985 | AA10: 12.133 | AB10: 40.672 | AC10: 40.82 | AD10: 11.606 | AE10: 38.363 | AF10: 8.031 | AG10: 13.714 | AH10: 12.742 | AJ10: =SUM(B10:AI10) -> 584.495
A12: IAD
A13: 300 | B13: 13.043 | C13: 34.028 | D13: 22.357 | E13: 56.007 | F13: 35.214 | G13: 25 | H13: 25.01 | I13: 11.938 | J13: 27.773 | AJ13: =SUM(B13:AI13) -> 250.37
A14: 225 | B14: 9.897 | C14: 8.824 | D14: 43.426 | E14: 4.072 | F14: 27 | G14: 6.659 | H14: 7.377 | I14: 26.976 | AJ14: =SUM(B14:AI14) -> 134.231
A15: 200 | B15: 27.146 | C15: 25.327 | D15: 35.351 | E15: 35.045 | AJ15: =SUM(B15:AI15) -> 122.869
A16: 150 | B16: 23.144 | C16: 46.863 | D16: 31.318 | E16: 25.005 | AJ16: =SUM(B16:AI16) -> 126.33
A17: 100 | B17: 31.156 | AJ17: =SUM(B17:AI17) -> 31.156
A23: Stage 3, 4, 5, 6
A24: Road Drainage
A25: 900
A26: =A25-75 -> 825
A27: =A26-75 -> 750 | B27: 88.332 | C27: 50.214 | D27: 13.211 | E27: 30.077 | F27: 14.417 | G27: 14.417 | H27: 41.867 | AJ27: =SUM(B27:AI27) -> 252.535
A28: =A27-75 -> 675
A29: =A28-75 -> 600 | B29: 9.768 | C29: 9.768 | D29: 10.35 | E29: 10.35 | F29: 8.759 | G29: 8.759 | H29: 16.516 | I29: 28.535 | J29: 28.118 | K29: 41.502 | L29: 7.757 | M29: 7.757 | N29: 8.01 | O29: 8.01 | AJ29: =SUM(B29:AI29) -> 203.959
A30: =A29-75 -> 525 | B30: 44.729 | AJ30: =SUM(B30:AI30) -> 44.729
A31: =A30-75 -> 450 | B31: 8.064 | C31: 37.596 | D31: 10.604 | E31: 8.142 | F31: 41.323 | G31: 12.203 | H31: 12.203 | I31: 12.203 | J31: 7.06 | K31: 7.06 | L31: 7.06 | M31: 4.698 | N31: 4.698 | O31: 4.698 | AJ31: =SUM(B31:AI31) -> 177.612
A32: =A31-75 -> 375 | B32: 62.41 | C32: 10.225 | D32: 7.962 | E32: 45.098 | F32: 19.937 | G32: 8.137 | H32: 12.88 | I32: 8.032 | J32: 21.536 | K32: 44.601 | L32: 28.324 | M32: 8.115 | N32: 9.603 | O32: 56.758 | P32: 50.26 | Q32: 7.658 | R32: 15.921 | S32: 39.47 | T32: 8.871 | AJ32: =SUM(B32:AI32) -> 465.798
A34: IAD
A35: 300 | B35: 16.448 | C35: 3.909 | D35: 16.604 | E35: 18.198 | AJ35: =SUM(B35:AI35) -> 55.159
A36: 225 | B36: 6.513 | C36: 39.913 | D36: 22.452 | E36: 18.342 | F36: 20.518 | G36: 26.607 | H36: 20.88 | I36: 17.294 | J36: 7.056 | K36: 34.636 | L36: 9.031 | M36: 3.226 | N36: 18.679 | O36: 21.242 | P36: 24.117 | Q36: 25.471 | R36: 9.388 | AJ36: =SUM(B36:AI36) -> 325.365
A37: 200 | B37: 20.307 | C37: 20.177 | AJ37: =SUM(B37:AI37) -> 40.484
A38: 150 | B38: 20.257 | C38: 25.069 | AJ38: =SUM(B38:AI38) -> 45.326
A43: Trunk Road
A44: 750 | B44: 17.342 | AJ44: =SUM(B44:AI44) -> 17.342
A45: 675 | B45: 41.931 | C45: 16.337 | AJ45: =SUM(B45:AI45) -> 58.268
A46: 375 | B46: 23.687 | C46: 11.131 | AJ46: =SUM(B46:AI46) -> 34.818
